Workbook
Name Cal_Endtime: 0.999305555555556
Name Calendar10Month: Calendar!$B$137
Name Calendar10MonthOption: MATCH(Calendar10Month,Months,0)
Name Calendar10Year: Calendar!$H$137
Name Calendar11Month: Calendar!$B$152
Name Calendar11MonthOption: MATCH(Calendar11Month,Months,0)
Name Calendar11Year: Calendar!$H$152
Name Calendar12Month: Calendar!$B$167
Name Calendar12MonthOption: MATCH(Calendar12Month,Months,0)
Name Calendar12Year: Calendar!$H$167
Name Calendar1Month: Calendar!$B$2
Name Calendar1MonthOption: MATCH(Calendar1Month,Months,0)
Name Calendar1Year: Calendar!$H$2
Name Calendar2Month: Calendar!$B$17
Name Calendar2MonthOption: MATCH(Calendar2Month,Months,0)
Name Calendar2Year: Calendar!$H$17
Name Calendar3Month: Calendar!$B$32
Name Calendar3MonthOption: MATCH(Calendar3Month,Months,0)
Name Calendar3Year: Calendar!$H$32
Name Calendar4Month: Calendar!$B$47
Name Calendar4MonthOption: MATCH(Calendar4Month,Months,0)
Name Calendar4Year: Calendar!$H$47
Name Calendar5Month: Calendar!$B$62
Name Calendar5MonthOption: MATCH(Calendar5Month,Months,0)
Name Calendar5Year: Calendar!$H$62
Name Calendar6Month: Calendar!$B$77
Name Calendar6MonthOption: MATCH(Calendar6Month,Months,0)
Name Calendar6Year: Calendar!$H$77
Name Calendar7Month: Calendar!$B$92
Name Calendar7MonthOption: MATCH(Calendar7Month,Months,0)
Name Calendar7Year: Calendar!$H$92
Name Calendar8Month: Calendar!$B$107
Name Calendar8MonthOption: MATCH(Calendar8Month,Months,0)
Name Calendar8Year: Calendar!$H$107
Name Calendar9Month: Calendar!$B$122
Name Calendar9MonthOption: MATCH(Calendar9Month,Months,0)
Name Calendar9Year: Calendar!$H$122
Name ColumnTitleRegion1..H12.1: Calendar!$B$3
Name ColumnTitleRegion10..H54.1: Calendar!$B$48
Name ColumnTitleRegion11..C56.1: Calendar!$B$48
Name ColumnTitleRegion12..D56.1: Calendar!$D$59
Name ColumnTitleRegion13..H68.1: Calendar!$B$63
Name ColumnTitleRegion14..C70.1: Calendar!$B$63
Name ColumnTitleRegion15..D70.1: Calendar!$D$74
Name ColumnTitleRegion16..H82.1: Calendar!$B$78
Name ColumnTitleRegion17..C84.1: Calendar!$B$78
Name ColumnTitleRegion18..D84.1: Calendar!$D$89
Name ColumnTitleRegion19..H96.1: Calendar!$B$93
Name ColumnTitleRegion2..C14.1: Calendar!$B$3
Name ColumnTitleRegion20..C98.1: Calendar!$B$93
Name ColumnTitleRegion21..D98.1: Calendar!$D$104
Name ColumnTitleRegion22..H110.1: Calendar!$B$108
Name ColumnTitleRegion23..C112.1: Calendar!$B$108
Name ColumnTitleRegion24..D112.1: Calendar!$D$119
Name ColumnTitleRegion25..H124.1: Calendar!$B$123
Name ColumnTitleRegion26..C126.1: Calendar!$B$123
Name ColumnTitleRegion27..D126.1: Calendar!$D$134
Name ColumnTitleRegion28..H138.1: Calendar!$B$138
Name ColumnTitleRegion29..C140.1: Calendar!$B$138
Name ColumnTitleRegion3..D14.1: Calendar!$D$14

Sheet Phase 1
A1: Vital Tracer Project - Phase 1 | H1: Patient Encounter | J1: Spectrophotometer | K1: Pulse Oximeter | M1: ABG | N1: Wave Form | T1: Patient Encounter | V1: Pulseoximeter | W1: ABG | X1: Spectrophotometer | AA1: Patient Encounter | AC1: Pulseoximeter | AD1: ABG | AE1: Spectrophotometer
A2: 1. Project Overview | B2: 2. Research Plan proposed on Jul 23 | C2: 3. Exploring dataset | D2: 4. Research Plan - Discussion | E2: 5. Research Plan - Counter Proposal | H2: Patient | I2: Encounter | J2: Spectrophotometer | K2: Device | L2: Pulseoximeter | M2: Blood gas | N2: 2HZ | O2: PPG | P2: 150Hz | T2: Patient | U2: Encounter | V2: Pulseoximeter | W2: Blood gas | X2: Spectrophotometer | AA2: Patient | AB2: Encounter | AC2: Pulseoximeter | AD2: Blood gas | AE2: Spectrophotometer
A3: The Phase 1 of the Project focuses on: (1) exploring the Openoximetry Respiratory (v1.0.0) dataset from PhysioNet (Link: https://physionet.org/content/openox-repo/1.0.0/) (2) leveraging the data to develop a machine learning (ML) model aimed at predicting a more accurate SpO2 value which is close to the gold standard SaO2 value extracted from ABG. | B3: - Build a classification ML model with: + Target value: SaO2 from ABG (continuous number) + Features: demographic variables (age, sex, race, ethnicity), dermatological variables (skin tone scale), and waveform variables (PPG RED/IR -> AC/DC, ETCO2, …) - Feature Engineering - Evaluation by Calibration Curve - Skin tone classification | C3: - There are 9 types of files, which could be grouped into 5 main groups (see table on the right): + Patient Encounter: Patient, Encounter + Spectrophotometer: Spectrophotometer + Pulse Oximeter: Device, Pulseoximeter + ABG: Bloodgas + Wave Form data: 2HZ, PPG, Base Data that cannot/will not be used for SpO2 enhancement model: - The Wave Form data category seems missing a lot of data, and hence, cannot be used. In addition to this, PPG and Base files do not have sample_id, which is used to linked with the ABG data. - Patient: + Race contains many values that have no description (1,2,3,4 ...) + Ethnicity: contains only 2 values, Hispanic or not, which does not provide much insights. - Encounter: + Monk scale: obtains the scales for different position, and cannot trace the exact position/area of measurement, except monk scale for fingernail which could be helpful in some cases. + Finger device: can trace back for approx. 67% in the pulseoximeter file, but it seems not carrying much insights + Finger diameter: not in the scope of this study. - Spectrophotometer: most columns cannot be used since we cannot track the position/area of measurement, except observations of group 'fingernail' - Device: device types and light types are ignored as it seems to be a limitation of our study | D3: - The target value is SaO2 whose data type is a continuous number; therefore, the suitable model is regression. - The waveform variables have too much missing values; therefore, it is impossible to put them into the model. - The skin tone classification can have some approach as below: + the target skin tone for monk scale/fitzpatrick in the encounter file are qualitative. + the features are all the quantitative variables in the spectrophotometer. + critical questions: how trustful is the qualitative skin tone scale? how well the monk scale and fitzpatrick scale address the quality of measuring lights for SpO2 even though we know that the different skin tone would impact the quality of Pulse SpO2 measurement? -> possible approach: create new labels for skin tone based on unsupervised learning technique and evaluate it based on the performance of the supervised learning model used for SpO2 enhancement? + other concern: the quantitative data have 3 different values for each patient_encounter, what is the value that we use for model training? -> possible approach: should we use the average value? or should we just keep all different values for each patient_encounter (x3 ) Therefore, to build a regression ML model, given all the waveform data is impossible to use, we have to use the provided Pulse SpO2 as the main indicator for the digital measured equipments/devices. | E3: PROPOSAL 1: Build ML regression model with Fitzpatrick's skin tone scale - Target value: SaO2 - Features: demographic variables (age, sex), dermatological variables (fitzpatrick scale), and Pulseoximeter variable (SpO2 and maybe pi) PROPOSAL 2: Build ML regression model with Monk's skin tone scale - Target value: SaO2 - Features: demographic variables (age, sex), dermatological variables (monk scale for fingernail (less observations)), and Pulseoximeter variable (SpO2 and maybe pi) PROPOSAL 3: Build ML regression model with ML supervised model for skin tone classification based on spectrophotometer data - Target value: SaO2 - Features: demographic variables (age, sex) and dermatological variables (monk scale for fingernail: train model -> predict -> full observations), and Pulseoximeter variable (SpO2 and maybe pi) PROPOSAL 4: Build ML regression model and ML unsupervied model for skin tone classification (clustering) based on spectrophotometer data - Target value: SaO2 - Features: demographic variables (age, sex) and dermatological variables (skin tone clusters from unsupervised learning model: train model -> clustering -> full observations), and Pulseoximeter variable (SpO2 and maybe pi) | H3: patient_id | I3: patient_id | J3: patient_id | K3: device_number | L3: encounter_id | M3: patient_id | N3: encounter_id* | O3: encounter_id* | P3: encounter_id* | T3: patient_id | U3: patient_id | V3: encounter_id | W3: patient_id | X3: patient_id | AA3: patient_id | AB3: patient_id | AC3: encounter_id | AD3: patient_id | AE3: patient_id
H4: site_id | I4: encounter_id | J4: encounter_id | K4: device_type | L4: device | M4: encounter_id | N4: Sample | O4: RED | P4: ECG-II | T4: assigned_sex | U4: encounter_id | V4: sample_number | W4: encounter_id | X4: encounter_id | AA4: assigned_sex | AB4: encounter_id | AC4: device | AD4: encounter_id | AE4: encounter_id
H5: assigned_sex | I5: encounter_date | J5: group | K5: light_type | L5: probe_location | M5: type | N5: ETCO2 | O5: IR | P5: ETO2 | U5: age_at_encounter | V5: saturation | W5: sample | X5: group | AB5: age_at_encounter | AC5: probe_location | AD5: sample | AE5: group
H6: race | I6: age_at_encounter | J6: date | L6: sample_number | M6: date | N6: ETO2 | P6: ETCO2 | U6: fitzpatrick | V6: pi | W6: so2 | X6: date | AB6: fitzpatrick | AC6: sample_number | AD6: so2 | AE6: date
H7: ethnicity | I7: warming | J7: melanin_index | L7: saturation | M7: time | N7: ScalcO2 | P7: RR | X7: melanin_index | AC7: saturation | AE7: melanin_index
I8: fitzpatrick | J8: hb_index | L8: pi | M8: sample | N8: RR | P8: ART | U8: monk_fingernail | X8: hb_index | AB8: monk_fingernail | AC8: pi | AE8: hb_index
I9: monk_fingernail | J9: hb_so2_index | M9: ph | N9: dev60_SpO2 | U9: monk_dorsal | X9: hb_so2_index | AB9: monk_dorsal | AE9: hb_so2_index
I10: monk_dorsal | J10: hue | M10: pco2 | N10: dev60_HR | U10: monk_palmar | X10: hue | AB10: monk_palmar | AE10: hue
I11: monk_palmar | J11: value | M11: po2 | N11: dev60_PI | U11: monk_upper_arm | X11: value | AB11: monk_upper_arm | AE11: value
I12: monk_upper_arm | J12: chroma | M12: so2 | N12: dev59_SpO2 | U12: monk_forehead | X12: chroma | AB12: monk_forehead | AE12: chroma
I13: monk_forehead | J13: lab_l | M13: cohb | N13: dev59_HR | X13: lab_l | AE13: lab_l
I14: finger_l1_device | J14: lab_a | M14: methb | N14: dev59_PI | R14: send email to PhysioNet | X14: lab_a | AE14: lab_a
I15: finger_l2_device | J15: lab_b | M15: thb | N15: Timestamp | R15: sample_id for ppg | X15: lab_b | AE15: lab_b
I16: finger_l3_device | J16: km400 | M16: k | R16: # of people per monk scale | X16: km400 | AE16: km400
I17: finger_l4_device | J17: km410 | M17: na | R17: 150HZ, 2HZ mean | X17: km410 | AE17: km410
I18: finger_l5_device | J18: km420 | M18: ca | X18: km420 | AE18: km420
I19: finger_r1_device | J19: km430 | M19: cl | X19: km430 | AE19: km430
I20: finger_r2_device | J20: km440 | M20: glucose | X20: km440 | AE20: km440
I21: finger_r3_device | J21: km450 | M21: lactate | X21: km450 | AE21: km450
I22: finger_r4_device | J22: km460 | M22: p50 | R22: clarify in 14 samples, how many subjects are theire (monk scale distribution) | X22: km460 | AE22: km460
I23: finger_r5_device | J23: km470 | M23: cbase | R23: feature important for all vs monk scale | X23: km470 | AE23: km470
I24: finger_l1_diameter | J24: km480 | M24: ETCO2 | R24: update the legend color based on monk scale | X24: km480 | AE24: km480
I25: finger_l2_diameter | J25: km490 | M25: ETO2 | X25: km490 | AE25: km490
I26: finger_l3_diameter | J26: km500 | M26: ScalcO2 | X26: km500 | AE26: km500
I27: finger_l4_diameter | J27: km510 | M27: RR | X27: km510 | AE27: km510
I28: finger_l5_diameter | J28: km520 | M28: dev60_HR | X28: km520 | AE28: km520
I29: finger_r1_diameter | J29: km530 | M29: dev55_HR | X29: km530 | AE29: km530
I30: finger_r2_diameter | J30: km540 | M30: dev59_HR | X30: km540 | AE30: km540
I31: finger_r3_diameter | J31: km550 | M31: dev64_HR | X31: km550 | AE31: km550
I32: finger_r4_diameter | J32: km560 | X32: km560 | AE32: km560
I33: finger_r5_diameter | J33: km570 | X33: km570 | AE33: km570
J34: km580 | X34: km580 | AE34: km580
J35: km590 | X35: km590 | AE35: km590
J36: km600 | X36: km600 | AE36: km600
J37: km610 | X37: km610 | AE37: km610
J38: km620 | X38: km620 | AE38: km620
J39: km630 | X39: km630 | AE39: km630
J40: km640 | X40: km640 | AE40: km640
...

Sheet Overview
A1: Link to instructional page | B1: https://physionet.org/content/openox-repo/1.0.0/
A2: Dataset | B2: OpenOximetry Repository
A3: Data Abstract | B3: The OpenOximetry Repository is a structured database designed to store clinical and laboratory pulse oximetry data and allows for consolidation of data sets held by collaborating organizations. Matched or independent readings of oxygen saturations, arterial blood gas samples, high frequency processed and unprocessed waveforms, and other physiologic metadata are supported (e.g. skin color readings).
C15: Non-invasive arterial blood pressure measurement and SpO2 estimation using PPG signal: a deep learning framework | BMC Medical Informatics and Decision Making | Full Text (biomedcentral.com)
A35: https://openoximetry.org/skin-color-quantification/
A36: https://skintone.google/get-started
A86: use wave length to find skin-tone
A87: Reflectance spectrophotometry is a method used to measure the reflectance of light from the skin at various wavelengths. While it does indeed depend on factors like blood oxygenation, pulse, and other physiological variables, it can be carefully controlled and calibrated to measure skin color accurately.

Sheet Field knowledge
A1: https://hypoxialab.com/sponsored-research/
A2: https://www.statnews.com/2022/12/05/unbiased-pulse-oximeters-researchers-need-better-way-to-measure-skin-tone/#:~:text=Monk's%20scale%20has%2010%20shades,represent%20medium%20and%20darker%20shades
A3: “To get pulse oximetry that works for everyone, we’re going to need to think very deeply about skin tone.” ELLIS MONK, HARVARD ASSOCIATE PROFESSOR OF SOCIOLOGY | B3: The light used in the devices to detect oxygenated blood can be blocked by melanin in the skin. | C3: And race has long been a proxy for skin tone in research studies because it’s something that’s recorded in both medical and census records, while skin tone is not. The medical studies that have come out highlighting that the devices missed dangerously low oxygen levels in patients with darker skin used race as well. | D3: But the two are very different. People who are Black can have a huge variety of skin tones, ranging from very dark to very light. And some people who are Asian, Hispanic, or Indigenous have darker skin than people who are Black.
D7: https://www.youtube.com/watch?v=MHPgamGQmDY | E7: https://www.youtube.com/watch?v=bVYOWuJlgEs
A8: The fifth vital signs: (1) Body temperature (2) Pulse rate (3) Respiration rate (4) Blood pressure (5) Blood oxygen level | B8: Pulse oximeters work by shining two types of lights: (1) infrared (2) red through your fingers and measure how much of both types of light are absorbed | C8: Factors can impact the accuracy: (1) moving hands (2) fingers are cold (3) anemia (4) poor circulation (5) wearing nail polish (6) melanin in the skin *** --> poor performance of the device on darker skin tone. | D8: Pulse Oximeter - Monitoring System Components: (1) Biological variables: oxygenated Haemoglobin and Deoxygenated Haemoglobin -> different light absorption depending on light wave lengths. (2) Sensor: consists of a pair of light-emitting diodes -> - monochromatic red light: 660 nanometers - monochromatic infrared light: 940 nanometers (cannot see) --> it's because oxygenated Hgb and deoxygenated Hgb have very different absorbative properties -> calculate the proportion of each type that is present. -> photodiode -> electrical signal. (3) Integrator - absorption + time -> AC/DC for 660 and 940 nm -> R values -> SpO2 (4) Output | E8: SpO2 -> Saturation of Peripheral Oxygen -> how saturated Hgb is with oxygen

Sheet Vinh's Project Analysis
A1: Quick Overview | E1: Project Summary
A2: Key aspect | B2: Description | C2: Column1 | E2: 1. Project Overview | F2: 2. Problem Statement | G2: 3. Approach
A3: Problem | B3: Pulse oximetric device measure light absoprtion to estimate Pulse SpO2. However, there are a number of factors impact the accuracy of the device's estimation: (1) moving (2) temperature (3) anemia (4) poor circulation (5) device type (6) measured area (7) device fitness (size) (8) skin tone | E3: This project focuses on leveraging the Openoximetry Respiratory dataset from PhysioNet to develop a machine learning (ML) model aimed at improving the accuracy of Pulse SpO2 estimation for Vital Tracer's devices. | F3: Accurate estimation of Pulse SpO2 is critical for monitoring respiratory and cardiovascular health. Current methods and devices may suffer from inaccuracies due to various factors such as motion artifacts, skin tone variations, anemia, device, etc. These inaccuracies can lead to unreliable health monitoring and potentially adverse health outcomes. | G3: To enhance the SpO2 estimation, it is essential to find an approximate delta SpO2 between the estimation vs the gold standard "SpO2" from the blood gas sample based on several important and collectable features. After identifying the features, they are then used to train a regression ML model to predict the good amount of delta to adjust for each set of feature combination. Suggested Features that are important and collectable: age, gender, skin tone, etc. (see the below table for possible data) Suggested Models: Linear Regression, FeedForwardNetwork, RandomForestRegressor
A4: Objective | B4: -> original Objective: improve SpO2 estimation from Vital Tracer's device -> paraphrased Objective: find delta (SpO2) to adjust the estimation based on some provided features: skin tone, probe location, device type, etc. (the features will be defined/selected later) | C4: Calibration curve from SaO2 Labl: SaO2
A5: Data Source | B5: PhysioNet - Openoximetry Respiratory (version 1.0.0) Link: https://physionet.org/content/openox-repo/1.0.0/
A8: Baseline Comparison | E8: Possible Data for ML model to estimate delta SpO2 for Pulse SpO2 enhancement
A9: Feature | B9: Openoximetry dataset | C9: Vital Tracer | E9: File | F9: Feature | G9: PK/FK
A10: Device | B10: 1, Handheld 2, Fingertip 3, Tabletop | C10: VT-Watch, VT-Patch | E10: devices | F10: device_number | G10: device_number
A11: Measured area | B11: fingernail, dorsal, palmar, forehead, upper arm, etc. | C11: Wrist, ? | E11: devices | F11: device_type
A12: Skintone scale | B12: Monk scale (10 levels: A,B, C, … I, J) | C12: how to identify the scale? | E12: devices | F12: light_type
A13: Skintone measured at | B13: fingernail, dorsal, palmar, forehead, upper arm | E13: patient | F13: patient_id | G13: patient_id
A14: Wave length @ spectrophotometer | B14: 400nm -> 700nm | C14: is it the same or different wave lengths? | E14: patient | F14: assigned_sex
A15: Light type measured | B15: ~98% Transmittance, ~ 2% Reflectance | C15: Reflectance? | E15: encounter | F15: encounter_id | G15: encounter_id patient_id
E16: encounter | F16: age_at_encounter
E17: encounter | F17: fitzpatrick
E18: encounter | F18: monk_fingernail
E19: encounter | F19: monk_dorsal
E20: encounter | F20: monk_palmar
E21: encounter | F21: monk_upper_arm
E22: encounter | F22: monk_forehead
E23: pulseoximeter | F23: encounter_id | G23: encounter_id sample_number
F24: sample_number
F25: device
F26: saturation
E27: spectrophotometer | F27: patient_id | G27: patient_id encounter_id
F28: encounter_id
F29: group
F30: wave lenghth (km400->km700)
E31: blood gas | F31: patient_id | G31: patient_id encounter_id sample_number
F32: encounter_id
F33: sample_number
F34: so2

Sheet encounter_with_wfd
A1: Folder | B1: Encounter_id | C1: .dat (150hz) | D1: .hea (150hz) | E1: _ppg.dat (PPG) | F1: _ppg.hea (PPG) | G1: .csv (2hz) | H1: Total files | I1: 150hz | J1: PPG | K1: 2hz
A2: =LEFT(B2,1) -> 0 | B2: 010127ad5b956a85fcd298cee3290455908f5857aea0e45459f0c390bbf2089b | C2: =IFERROR(VLOOKUP(Table16[[#This Row],[Encounter_id]],'wf folder'!$B:$K,2,0),"No") -> No | D2: =IFERROR(VLOOKUP(Table16[[#This Row],[Encounter_id]],'wf folder'!$B:$K,3,0),"No") -> No | E2: =IFERROR(VLOOKUP(Table16[[#This Row],[Encounter_id]],'wf folder'!$B:$K,4,0),"No") -> No | F2: =IFERROR(VLOOKUP(Table16[[#This Row],[Encounter_id]],'wf folder'!$B:$K,5,0),"No") -> No | G2: =IFERROR(VLOOKUP(Table16[[#This Row],[Encounter_id]],'wf folder'!$B:$K,6,0),"No") -> No | H2: =IFERROR(VLOOKUP(Table16[[#This Row],[Encounter_id]],'wf folder'!$B:$K,7,0),0) -> 0 | I2: =IFERROR(VLOOKUP(Table16[[#This Row],[Encounter_id]],'wf folder'!$B:$K,8,0),"No") -> No | J2: =IFERROR(VLOOKUP(Table16[[#This Row],[Encounter_id]],'wf folder'!$B:$K,9,0),"No") -> No | K2: =IFERROR(VLOOKUP(Table16[[#This Row],[Encounter_id]],'wf folder'!$B:$K,10,0),"No") -> No
A3: =LEFT(B3,1) -> 0 | B3: 01b0a887f76a3f77a708ccff97cabb16b223e572c4bfd18c4ff02c443c0c88d3 | C3: =IFERROR(VLOOKUP(Table16[[#This Row],[Encounter_id]],'wf folder'!$B:$K,2,0),"No") -> No | D3: =IFERROR(VLOOKUP(Table16[[#This Row],[Encounter_id]],'wf folder'!$B:$K,3,0),"No") -> Yes | E3: =IFERROR(VLOOKUP(Table16[[#This Row],[Encounter_id]],'wf folder'!$B:$K,4,0),"No") -> No | F3: =IFERROR(VLOOKUP(Table16[[#This Row],[Encounter_id]],'wf folder'!$B:$K,5,0),"No") -> No | G3: =IFERROR(VLOOKUP(Table16[[#This Row],[Encounter_id]],'wf folder'!$B:$K,6,0),"No") -> No | H3: =IFERROR(VLOOKUP(Table16[[#This Row],[Encounter_id]],'wf folder'!$B:$K,7,0),0) -> 1 | I3: =IFERROR(VLOOKUP(Table16[[#This Row],[Encounter_id]],'wf folder'!$B:$K,8,0),"No") -> No | J3: =IFERROR(VLOOKUP(Table16[[#This Row],[Encounter_id]],'wf folder'!$B:$K,9,0),"No") -> No | K3: =IFERROR(VLOOKUP(Table16[[#This Row],[Encounter_id]],'wf folder'!$B:$K,10,0),"No") -> No
A4: =LEFT(B4,1) -> 0 | B4: 0218aa199ef6e05f9cb938222abf2d2a25d7214e34f9cc7a14ca8f20d7e47b5f | C4: =IFERROR(VLOOKUP(Table16[[#This Row],[Encounter_id]],'wf folder'!$B:$K,2,0),"No") -> Yes | D4: =IFERROR(VLOOKUP(Table16[[#This Row],[Encounter_id]],'wf folder'!$B:$K,3,0),"No") -> No | E4: =IFERROR(VLOOKUP(Table16[[#This Row],[Encounter_id]],'wf folder'!$B:$K,4,0),"No") -> No | F4: =IFERROR(VLOOKUP(Table16[[#This Row],[Encounter_id]],'wf folder'!$B:$K,5,0),"No") -> No | G4: =IFERROR(VLOOKUP(Table16[[#This Row],[Encounter_id]],'wf folder'!$B:$K,6,0),"No") -> Yes | H4: =IFERROR(VLOOKUP(Table16[[#This Row],[Encounter_id]],'wf folder'!$B:$K,7,0),0) -> 2 | I4: =IFERROR(VLOOKUP(Table16[[#This Row],[Encounter_id]],'wf folder'!$B:$K,8,0),"No") -> No | J4: =IFERROR(VLOOKUP(Table16[[#This Row],[Encounter_id]],'wf folder'!$B:$K,9,0),"No") -> No | K4: =IFERROR(VLOOKUP(Table16[[#This Row],[Encounter_id]],'wf folder'!$B:$K,10,0),"No") -> Yes
A5: =LEFT(B5,1) -> 0 | B5: 0241a26f4be08b7312eab3099fb7e044376d7d433d69cc15ed67742b0ecf95f5 | C5: =IFERROR(VLOOKUP(Table16[[#This Row],[Encounter_id]],'wf folder'!$B:$K,2,0),"No") -> No | D5: =IFERROR(VLOOKUP(Table16[[#This Row],[Encounter_id]],'wf folder'!$B:$K,3,0),"No") -> No | E5: =IFERROR(VLOOKUP(Table16[[#This Row],[Encounter_id]],'wf folder'!$B:$K,4,0),"No") -> No | F5: =IFERROR(VLOOKUP(Table16[[#This Row],[Encounter_id]],'wf folder'!$B:$K,5,0),"No") -> No | G5: =IFERROR(VLOOKUP(Table16[[#This Row],[Encounter_id]],'wf folder'!$B:$K,6,0),"No") -> No | H5: =IFERROR(VLOOKUP(Table16[[#This Row],[Encounter_id]],'wf folder'!$B:$K,7,0),0) -> 0 | I5: =IFERROR(VLOOKUP(Table16[[#This Row],[Encounter_id]],'wf folder'!$B:$K,8,0),"No") -> No | J5: =IFERROR(VLOOKUP(Table16[[#This Row],[Encounter_id]],'wf folder'!$B:$K,9,0),"No") -> No | K5: =IFERROR(VLOOKUP(Table16[[#This Row],[Encounter_id]],'wf folder'!$B:$K,10,0),"No") -> No
A6: =LEFT(B6,1) -> 0 | B6: 026237b8b5542bcc94e106231d499ee3bae833633c4d068b7b56fed33914ff12 | C6: =IFERROR(VLOOKUP(Table16[[#This Row],[Encounter_id]],'wf folder'!$B:$K,2,0),"No") -> No | D6: =IFERROR(VLOOKUP(Table16[[#This Row],[Encounter_id]],'wf folder'!$B:$K,3,0),"No") -> No | E6: =IFERROR(VLOOKUP(Table16[[#This Row],[Encounter_id]],'wf folder'!$B:$K,4,0),"No") -> No | F6: =IFERROR(VLOOKUP(Table16[[#This Row],[Encounter_id]],'wf folder'!$B:$K,5,0),"No") -> No | G6: =IFERROR(VLOOKUP(Table16[[#This Row],[Encounter_id]],'wf folder'!$B:$K,6,0),"No") -> No | H6: =IFERROR(VLOOKUP(Table16[[#This Row],[Encounter_id]],'wf folder'!$B:$K,7,0),0) -> 0 | I6: =IFERROR(VLOOKUP(Table16[[#This Row],[Encounter_id]],'wf folder'!$B:$K,8,0),"No") -> No | J6: =IFERROR(VLOOKUP(Table16[[#This Row],[Encounter_id]],'wf folder'!$B:$K,9,0),"No") -> No | K6: =IFERROR(VLOOKUP(Table16[[#This Row],[Encounter_id]],'wf folder'!$B:$K,10,0),"No") -> No
A7: =LEFT(B7,1) -> 0 | B7: 0274ff212eab782d3a29b533b78a051984a04469844659e3cab48bab230e2e1d | C7: =IFERROR(VLOOKUP(Table16[[#This Row],[Encounter_id]],'wf folder'!$B:$K,2,0),"No") -> No | D7: =IFERROR(VLOOKUP(Table16[[#This Row],[Encounter_id]],'wf folder'!$B:$K,3,0),"No") -> No | E7: =IFERROR(VLOOKUP(Table16[[#This Row],[Encounter_id]],'wf folder'!$B:$K,4,0),"No") -> Yes | F7: =IFERROR(VLOOKUP(Table16[[#This Row],[Encounter_id]],'wf folder'!$B:$K,5,0),"No") -> No | G7: =IFERROR(VLOOKUP(Table16[[#This Row],[Encounter_id]],'wf folder'!$B:$K,6,0),"No") -> No | H7: =IFERROR(VLOOKUP(Table16[[#This Row],[Encounter_id]],'wf folder'!$B:$K,7,0),0) -> 1 | I7: =IFERROR(VLOOKUP(Table16[[#This Row],[Encounter_id]],'wf folder'!$B:$K,8,0),"No") -> No | J7: =IFERROR(VLOOKUP(Table16[[#This Row],[Encounter_id]],'wf folder'!$B:$K,9,0),"No") -> No | K7: =IFERROR(VLOOKUP(Table16[[#This Row],[Encounter_id]],'wf folder'!$B:$K,10,0),"No") -> No
A8: =LEFT(B8,1) -> 0 | B8: 0309e8beaed31d56ddf6e1ef49459c3f34a8d948c08bd08746e7fe100a77ad59 | C8: =IFERROR(VLOOKUP(Table16[[#This Row],[Encounter_id]],'wf folder'!$B:$K,2,0),"No") -> No | D8: =IFERROR(VLOOKUP(Table16[[#This Row],[Encounter_id]],'wf folder'!$B:$K,3,0),"No") -> No | E8: =IFERROR(VLOOKUP(Table16[[#This Row],[Encounter_id]],'wf folder'!$B:$K,4,0),"No") -> No | F8: =IFERROR(VLOOKUP(Table16[[#This Row],[Encounter_id]],'wf folder'!$B:$K,5,0),"No") -> No | G8: =IFERROR(VLOOKUP(Table16[[#This Row],[Encounter_id]],'wf folder'!$B:$K,6,0),"No") -> No | H8: =IFERROR(VLOOKUP(Table16[[#This Row],[Encounter_id]],'wf folder'!$B:$K,7,0),0) -> 0 | I8: =IFERROR(VLOOKUP(Table16[[#This Row],[Encounter_id]],'wf folder'!$B:$K,8,0),"No") -> No | J8: =IFERROR(VLOOKUP(Table16[[#This Row],[Encounter_id]],'wf folder'!$B:$K,9,0),"No") -> No | K8: =IFERROR(VLOOKUP(Table16[[#This Row],[Encounter_id]],'wf folder'!$B:$K,10,0),"No") -> No
A9: =LEFT(B9,1) -> 0 | B9: 037bc14f7b51b6ec271834ff183199450ea9ec87628c61e5839d5a28b450a9af | C9: =IFERROR(VLOOKUP(Table16[[#This Row],[Encounter_id]],'wf folder'!$B:$K,2,0),"No") -> No | D9: =IFERROR(VLOOKUP(Table16[[#This Row],[Encounter_id]],'wf folder'!$B:$K,3,0),"No") -> No | E9: =IFERROR(VLOOKUP(Table16[[#This Row],[Encounter_id]],'wf folder'!$B:$K,4,0),"No") -> No | F9: =IFERROR(VLOOKUP(Table16[[#This Row],[Encounter_id]],'wf folder'!$B:$K,5,0),"No") -> No | G9: =IFERROR(VLOOKUP(Table16[[#This Row],[Encounter_id]],'wf folder'!$B:$K,6,0),"No") -> No | H9: =IFERROR(VLOOKUP(Table16[[#This Row],[Encounter_id]],'wf folder'!$B:$K,7,0),0) -> 0 | I9: =IFERROR(VLOOKUP(Table16[[#This Row],[Encounter_id]],'wf folder'!$B:$K,8,0),"No") -> No | J9: =IFERROR(VLOOKUP(Table16[[#This Row],[Encounter_id]],'wf folder'!$B:$K,9,0),"No") -> No | K9: =IFERROR(VLOOKUP(Table16[[#This Row],[Encounter_id]],'wf folder'!$B:$K,10,0),"No") -> No
A10: =LEFT(B10,1) -> 0 | B10: 039d6278a1f20423ec2955be8ae305283887dc67fc5f3a04aa17ac01172c5b2f | C10: =IFERROR(VLOOKUP(Table16[[#This Row],[Encounter_id]],'wf folder'!$B:$K,2,0),"No") -> No | D10: =IFERROR(VLOOKUP(Table16[[#This Row],[Encounter_id]],'wf folder'!$B:$K,3,0),"No") -> Yes | E10: =IFERROR(VLOOKUP(Table16[[#This Row],[Encounter_id]],'wf folder'!$B:$K,4,0),"No") -> No | F10: =IFERROR(VLOOKUP(Table16[[#This Row],[Encounter_id]],'wf folder'!$B:$K,5,0),"No") -> No | G10: =IFERROR(VLOOKUP(Table16[[#This Row],[Encounter_id]],'wf folder'!$B:$K,6,0),"No") -> Yes | H10: =IFERROR(VLOOKUP(Table16[[#This Row],[Encounter_id]],'wf folder'!$B:$K,7,0),0) -> 2 | I10: =IFERROR(VLOOKUP(Table16[[#This Row],[Encounter_id]],'wf folder'!$B:$K,8,0),"No") -> No | J10: =IFERROR(VLOOKUP(Table16[[#This Row],[Encounter_id]],'wf folder'!$B:$K,9,0),"No") -> No | K10: =IFERROR(VLOOKUP(Table16[[#This Row],[Encounter_id]],'wf folder'!$B:$K,10,0),"No") -> Yes
A11: =LEFT(B11,1) -> 0 | B11: 0480a264b06b03cc1b7c1080c6163a53c500532ad311bbf3a5bfb069e2eb5bd6 | C11: =IFERROR(VLOOKUP(Table16[[#This Row],[Encounter_id]],'wf folder'!$B:$K,2,0),"No") -> No | D11: =IFERROR(VLOOKUP(Table16[[#This Row],[Encounter_id]],'wf folder'!$B:$K,3,0),"No") -> Yes | E11: =IFERROR(VLOOKUP(Table16[[#This Row],[Encounter_id]],'wf folder'!$B:$K,4,0),"No") -> No | F11: =IFERROR(VLOOKUP(Table16[[#This Row],[Encounter_id]],'wf folder'!$B:$K,5,0),"No") -> No | G11: =IFERROR(VLOOKUP(Table16[[#This Row],[Encounter_id]],'wf folder'!$B:$K,6,0),"No") -> No | H11: =IFERROR(VLOOKUP(Table16[[#This Row],[Encounter_id]],'wf folder'!$B:$K,7,0),0) -> 1 | I11: =IFERROR(VLOOKUP(Table16[[#This Row],[Encounter_id]],'wf folder'!$B:$K,8,0),"No") -> No | J11: =IFERROR(VLOOKUP(Table16[[#This Row],[Encounter_id]],'wf folder'!$B:$K,9,0),"No") -> No | K11: =IFERROR(VLOOKUP(Table16[[#This Row],[Encounter_id]],'wf folder'!$B:$K,10,0),"No") -> No
A12: =LEFT(B12,1) -> 0 | B12: 05461beaa57c7ad2d35075d5e859d9b57465d3398629b737c1954d5288e02aeb | C12: =IFERROR(VLOOKUP(Table16[[#This Row],[Encounter_id]],'wf folder'!$B:$K,2,0),"No") -> No | D12: =IFERROR(VLOOKUP(Table16[[#This Row],[Encounter_id]],'wf folder'!$B:$K,3,0),"No") -> No | E12: =IFERROR(VLOOKUP(Table16[[#This Row],[Encounter_id]],'wf folder'!$B:$K,4,0),"No") -> No | F12: =IFERROR(VLOOKUP(Table16[[#This Row],[Encounter_id]],'wf folder'!$B:$K,5,0),"No") -> No | G12: =IFERROR(VLOOKUP(Table16[[#This Row],[Encounter_id]],'wf folder'!$B:$K,6,0),"No") -> No | H12: =IFERROR(VLOOKUP(Table16[[#This Row],[Encounter_id]],'wf folder'!$B:$K,7,0),0) -> 0 | I12: =IFERROR(VLOOKUP(Table16[[#This Row],[Encounter_id]],'wf folder'!$B:$K,8,0),"No") -> No | J12: =IFERROR(VLOOKUP(Table16[[#This Row],[Encounter_id]],'wf folder'!$B:$K,9,0),"No") -> No | K12: =IFERROR(VLOOKUP(Table16[[#This Row],[Encounter_id]],'wf folder'!$B:$K,10,0),"No") -> No
A13: =LEFT(B13,1) -> 0 | B13: 056bdfc31ca6c99edbd3763acae788bddaf66b51204507342c45497b4fa924c6 | C13: =IFERROR(VLOOKUP(Table16[[#This Row],[Encounter_id]],'wf folder'!$B:$K,2,0),"No") -> No | D13: =IFERROR(VLOOKUP(Table16[[#This Row],[Encounter_id]],'wf folder'!$B:$K,3,0),"No") -> No | E13: =IFERROR(VLOOKUP(Table16[[#This Row],[Encounter_id]],'wf folder'!$B:$K,4,0),"No") -> No | F13: =IFERROR(VLOOKUP(Table16[[#This Row],[Encounter_id]],'wf folder'!$B:$K,5,0),"No") -> No | G13: =IFERROR(VLOOKUP(Table16[[#This Row],[Encounter_id]],'wf folder'!$B:$K,6,0),"No") -> No | H13: =IFERROR(VLOOKUP(Table16[[#This Row],[Encounter_id]],'wf folder'!$B:$K,7,0),0) -> 0 | I13: =IFERROR(VLOOKUP(Table16[[#This Row],[Encounter_id]],'wf folder'!$B:$K,8,0),"No") -> No | J13: =IFERROR(VLOOKUP(Table16[[#This Row],[Encounter_id]],'wf folder'!$B:$K,9,0),"No") -> No | K13: =IFERROR(VLOOKUP(Table16[[#This Row],[Encounter_id]],'wf folder'!$B:$K,10,0),"No") -> No
... A460: =LEFT(B460,1) -> f | B460: ffcbe159f5e8ce8e81465af70eea01fa2607dac1cd0a4416f56a6de92c104d7e | C460: =IFERROR(VLOOKUP(Table16[[#This Row],[Encounter_id]],'wf folder'!$B:$K,2,0),"No") -> No | D460: =IFERROR(VLOOKUP(Table16[[#This Row],[Encounter_id]],'wf folder'!$B:$K,3,0),"No") -> No | E460: =IFERROR(VLOOKUP(Table16[[#This Row],[Encounter_id]],'wf folder'!$B:$K,4,0),"No") -> No | F460: =IFERROR(VLOOKUP(Table16[[#This Row],[Encounter_id]],'wf folder'!$B:$K,5,0),"No") -> No | G460: =IFERROR(VLOOKUP(Table16[[#This Row],[Encounter_id]],'wf folder'!$B:$K,6,0),"No") -> No | H460: =IFERROR(VLOOKUP(Table16[[#This Row],[Encounter_id]],'wf folder'!$B:$K,7,0),0) -> 0 | I460: =IFERROR(VLOOKUP(Table16[[#This Row],[Encounter_id]],'wf folder'!$B:$K,8,0),"No") -> No | J460: =IFERROR(VLOOKUP(Table16[[#This Row],[Encounter_id]],'wf folder'!$B:$K,9,0),"No") -> No | K460: =IFERROR(VLOOKUP(Table16[[#This Row],[Encounter_id]],'wf folder'!$B:$K,10,0),"No") -> No
E465: send email re missing ppg files

Sheet Tables
A1: Table Name | B1: Description | C1: Check
A2: patient | B2: This file contains information about individual patients/participants that are taking part in the study. Basic, relatively immutable information is included in this file, with each participant having one row in the participants file. Participants are given a unique participant ID so that they can be identified between encounters (i.e. each participant may have many encounters). Additionally, information about the site that is conducting the study is included in this file so that participants can be selected and stratified by site if desired during analysis. | C2: Y
A3: encounter | B3: This file contains information from each controlled desaturation “breathe down” encounter. Each row of the encounter table includes information from a single encounter (so examining a single encounter requires looking at only one row of the encounter table; this is not the case for other files). Each encounter corresponds to one participant (i.e. each row has one participant ID). Information about which device is used on which finger, finger diameter, and measurements made during the encounter are included in this file. Qualitative skin color measurements are also included here (e.g. Monk scale). Dates in the encounter table are offset into the future by a random offset (set per participant) while attempting to preserve seasonality to de-identify the dataset.This preserves intra-participant chronology while inter-participant chronology is obscured.'
A4: pulseoximeter | B4: This table contains pulse oximeter saturation readings for the different test devices. Each row contains one saturation reading from one pulse oximeter, corresponding to a specific encounter (desaturation session or clinical encounter, identified by encounter_id), and a specific blood gas within that encounter (identified by sample_number).
A5: spectrophotometer | B5: This table contains quantitative skin color data. Each row represents one spectrophotometer measurement at a single anatomic site. Spectrophotometer measurements are typically taken three times at each anatomic site, and repeated at each encounter. They are linked to the encounter via encounter_id, and to the patient via patient_id.
A6: bloodgas | B6: The blood gas table contains blood gas measurements and data obtained at the same time as the blood gas. Each row represents the results from a single blood gas sample and clinical data from that time. These samples are linked to pulse oximeter readings and other data during the same encounter via 'sample_number' and 'encounter_id'.
A7: device | B7: The device table contains descriptive data about the pulse oximeters. Each row contains data for one pulse oximeter model and includes a unique device ID number, as well as the make, model, and light transmission mode of the oximeter.
A8: base waveforms | B8: Continuous data contained here includes ECG, oxygen and carbon dioxide in mmHg, respiratory rate, and blood pressure in mmHg in WFDB format. NB: if data is available from a continuous source, it is not entered in the 'bloodgas' table, but may be linked to a specific blood gas sample via 'encounter_id', and 'sample_number' or date and time.
A9: 2hz | B9: Reference oximeter readings (2Hz, file suffix _2hz): Continuous data from devices used as known reference oximeters during a encounter are included as csv files. These files contain SpO2, HR, and pulsatility index (PI) recorded at 2Hz. The calculated saturation (ScalcO2) is the instantaneously estimated SaO2 based on ETO2. Blood sample draws are labeled and correspond to the ‘sample’ number in other tables.
A10: ppg | B10: Raw PPG (86hz, file suffix _ppg): Raw PPG is included for certain encounters, and PPG files are named according to their corresponding encounter. However in this version of the database, they are not time-synchronized to the other waveform data from the same encounter.

Sheet Sheet1
A4: 1.1 Email data providers and request for sample ID for PPG signals, number of subjects per Monk scale group and spo2 data. | B4: x
A5: 1.2 Update the Molk scale visualization with the correct colour ordering from light to dark skin tones | B5: x
A6: 1.3 Analyze other features besides LAB for correlation with Monk Scale and perform feature important analysis
A9: Break-down the number of patients, encounters in for Monk_scale distribution data
A11: File error: - PI number in 2HZ file - the UOM of the waveform in the basefile
A14: BUILD ML based on signal features: CNN LSTM | B14: more epochs, LSTM
A16: reminder email
A17: draft email for classfication: what is the label

Sheet Calendar
B2: July | H2: 2024
B3: MONDAY | C3: =UPPER(TEXT(C4,"dddd")) -> TUESDAY | D3: =UPPER(TEXT(D4,"dddd")) -> WEDNESDAY | E3: =UPPER(TEXT(E4,"dddd")) -> THURSDAY | F3: =UPPER(TEXT(F4,"dddd")) -> FRIDAY | G3: =UPPER(TEXT(G4,"dddd")) -> SATURDAY | H3: =UPPER(TEXT(H4,"dddd")) -> SUNDAY
B4: {=Days+1+DATE(Calendar1Year,Calendar1MonthOption,1)-WEEKDAY(DATE(Calendar1Year,Calendar1MonthOption,1),WeekdayOption)} -> 45474 | C4: 45475 | D4: 45476 | E4: 45477 | F4: 45478 | G4: 45479 | H4: 45480
B6: {=Days+8+DATE(Calendar1Year,Calendar1MonthOption,1)-WEEKDAY(DATE(Calendar1Year,Calendar1MonthOption,1),WeekdayOption)} -> 45481 | C6: 45482 | D6: 45483 | E6: 45484 | F6: 45485 | G6: 45486 | H6: 45487
B8: {=Days+15+DATE(Calendar1Year,Calendar1MonthOption,1)-WEEKDAY(DATE(Calendar1Year,Calendar1MonthOption,1),WeekdayOption)} -> 45488 | C8: 45489 | D8: 45490 | E8: 45491 | F8: 45492 | G8: 45493 | H8: 45494
F9: WT - Prof Viji - present findings @ 12:30pm
B10: {=Days+22+DATE(Calendar1Year,Calendar1MonthOption,1)-WEEKDAY(DATE(Calendar1Year,Calendar1MonthOption,1),WeekdayOption)} -> 45495 | C10: 45496 | D10: 45497 | E10: 45498 | F10: 45499 | G10: 45500 | H10: 45501
C11: WT - Prof Viji - present findings @ 12:30pm | F11: WT - Prof Viji - present findings @ 17:30pm
B12: {=Days+29+DATE(Calendar1Year,Calendar1MonthOption,1)-WEEKDAY(DATE(Calendar1Year,Calendar1MonthOption,1),WeekdayOption)} -> 45502 | C12: 45503 | D12: 45504 | E12: 45505 | F12: 45506 | G12: 45507 | H12: 45508
B14: {=Days+36+DATE(Calendar1Year,Calendar1MonthOption,1)-WEEKDAY(DATE(Calendar1Year,Calendar1MonthOption,1),WeekdayOption)} -> 45509 | C14: 45510 | D14: Notes:
B17: =TEXT(DATE(Calendar1Year,Calendar1MonthOption+1,1),"mmmm") -> August | H17: =YEAR(DATE(Calendar1Year,Calendar1MonthOption+1,1)) -> 2024
B18: =UPPER(TEXT(B19,"dddd")) -> MONDAY | C18: =UPPER(TEXT(C19,"dddd")) -> TUESDAY | D18: =UPPER(TEXT(D19,"dddd")) -> WEDNESDAY | E18: =UPPER(TEXT(E19,"dddd")) -> THURSDAY | F18: =UPPER(TEXT(F19,"dddd")) -> FRIDAY | G18: =UPPER(TEXT(G19,"dddd")) -> SATURDAY | H18: =UPPER(TEXT(H19,"dddd")) -> SUNDAY
B19: {=Days+1+DATE(Calendar2Year,Calendar2MonthOption,1)-WEEKDAY(DATE(Calendar2Year,Calendar2MonthOption,1),WeekdayOption)} -> 45502 | C19: 45503 | D19: 45504 | E19: 45505 | F19: 45506 | G19: 45507 | H19: 45508
B21: {=Days+8+DATE(Calendar2Year,Calendar2MonthOption,1)-WEEKDAY(DATE(Calendar2Year,Calendar2MonthOption,1),WeekdayOption)} -> 45509 | C21: 45510 | D21: 45511 | E21: 45512 | F21: 45513 | G21: 45514 | H21: 45515
B23: {=Days+15+DATE(Calendar2Year,Calendar2MonthOption,1)-WEEKDAY(DATE(Calendar2Year,Calendar2MonthOption,1),WeekdayOption)} -> 45516 | C23: 45517 | D23: 45518 | E23: 45519 | F23: 45520 | G23: 45521 | H23: 45522
B25: {=Days+22+DATE(Calendar2Year,Calendar2MonthOption,1)-WEEKDAY(DATE(Calendar2Year,Calendar2MonthOption,1),WeekdayOption)} -> 45523 | C25: 45524 | D25: 45525 | E25: 45526 | F25: 45527 | G25: 45528 | H25: 45529
B27: {=Days+29+DATE(Calendar2Year,Calendar2MonthOption,1)-WEEKDAY(DATE(Calendar2Year,Calendar2MonthOption,1),WeekdayOption)} -> 45530 | C27: 45531 | D27: 45532 | E27: 45533 | F27: 45534 | G27: 45535 | H27: 45536
B29: {=Days+36+DATE(Calendar2Year,Calendar2MonthOption,1)-WEEKDAY(DATE(Calendar2Year,Calendar2MonthOption,1),WeekdayOption)} -> 45537 | C29: 45538 | D29: Notes:
B32: =TEXT(DATE(Calendar2Year,Calendar2MonthOption+1,1),"mmmm") -> September | H32: =YEAR(DATE(Calendar2Year,Calendar2MonthOption+1,1)) -> 2024
B33: =UPPER(TEXT(B34,"dddd")) -> MONDAY | C33: =UPPER(TEXT(C34,"dddd")) -> TUESDAY | D33: =UPPER(TEXT(D34,"dddd")) -> WEDNESDAY | E33: =UPPER(TEXT(E34,"dddd")) -> THURSDAY | F33: =UPPER(TEXT(F34,"dddd")) -> FRIDAY | G33: =UPPER(TEXT(G34,"dddd")) -> SATURDAY | H33: =UPPER(TEXT(H34,"dddd")) -> SUNDAY
B34: {=Days+1+DATE(Calendar3Year,Calendar3MonthOption,1)-WEEKDAY(DATE(Calendar3Year,Calendar3MonthOption,1),WeekdayOption)} -> 45530 | C34: 45531 | D34: 45532 | E34: 45533 | F34: 45534 | G34: 45535 | H34: 45536
B36: {=Days+8+DATE(Calendar3Year,Calendar3MonthOption,1)-WEEKDAY(DATE(Calendar3Year,Calendar3MonthOption,1),WeekdayOption)} -> 45537 | C36: 45538 | D36: 45539 | E36: 45540 | F36: 45541 | G36: 45542 | H36: 45543
B38: {=Days+15+DATE(Calendar3Year,Calendar3MonthOption,1)-WEEKDAY(DATE(Calendar3Year,Calendar3MonthOption,1),WeekdayOption)} -> 45544 | C38: 45545 | D38: 45546 | E38: 45547 | F38: 45548 | G38: 45549 | H38: 45550
B40: {=Days+22+DATE(Calendar3Year,Calendar3MonthOption,1)-WEEKDAY(DATE(Calendar3Year,Calendar3MonthOption,1),WeekdayOption)} -> 45551 | C40: 45552 | D40: 45553 | E40: 45554 | F40: 45555 | G40: 45556 | H40: 45557
B42: {=Days+29+DATE(Calendar3Year,Calendar3MonthOption,1)-WEEKDAY(DATE(Calendar3Year,Calendar3MonthOption,1),WeekdayOption)} -> 45558 | C42: 45559 | D42: 45560 | E42: 45561 | F42: 45562 | G42: 45563 | H42: 45564
B44: {=Days+36+DATE(Calendar3Year,Calendar3MonthOption,1)-WEEKDAY(DATE(Calendar3Year,Calendar3MonthOption,1),WeekdayOption)} -> 45565 | C44: 45566 | D44: Notes:
B47: =TEXT(DATE(Calendar3Year,Calendar3MonthOption+1,1),"mmmm") -> October | H47: =YEAR(DATE(Calendar3Year,Calendar3MonthOption+1,1)) -> 2024
B48: =UPPER(TEXT(B49,"dddd")) -> MONDAY | C48: =UPPER(TEXT(C49,"dddd")) -> TUESDAY | D48: =UPPER(TEXT(D49,"dddd")) -> WEDNESDAY | E48: =UPPER(TEXT(E49,"dddd")) -> THURSDAY | F48: =UPPER(TEXT(F49,"dddd")) -> FRIDAY | G48: =UPPER(TEXT(G49,"dddd")) -> SATURDAY | H48: =UPPER(TEXT(H49,"dddd")) -> SUNDAY
B49: {=Days+1+DATE(Calendar4Year,Calendar4MonthOption,1)-WEEKDAY(DATE(Calendar4Year,Calendar4MonthOption,1),WeekdayOption)} -> 45565 | C49: 45566 | D49: 45567 | E49: 45568 | F49: 45569 | G49: 45570 | H49: 45571
B51: {=Days+8+DATE(Calendar4Year,Calendar4MonthOption,1)-WEEKDAY(DATE(Calendar4Year,Calendar4MonthOption,1),WeekdayOption)} -> 45572 | C51: 45573 | D51: 45574 | E51: 45575 | F51: 45576 | G51: 45577 | H51: 45578
B53: {=Days+15+DATE(Calendar4Year,Calendar4MonthOption,1)-WEEKDAY(DATE(Calendar4Year,Calendar4MonthOption,1),WeekdayOption)} -> 45579 | C53: 45580 | D53: 45581 | E53: 45582 | F53: 45583 | G53: 45584 | H53: 45585
B55: {=Days+22+DATE(Calendar4Year,Calendar4MonthOption,1)-WEEKDAY(DATE(Calendar4Year,Calendar4MonthOption,1),WeekdayOption)} -> 45586 | C55: 45587 | D55: 45588 | E55: 45589 | F55: 45590 | G55: 45591 | H55: 45592
B57: {=Days+29+DATE(Calendar4Year,Calendar4MonthOption,1)-WEEKDAY(DATE(Calendar4Year,Calendar4MonthOption,1),WeekdayOption)} -> 45593 | C57: 45594 | D57: 45595 | E57: 45596 | F57: 45597 | G57: 45598 | H57: 45599
B59: {=Days+36+DATE(Calendar4Year,Calendar4MonthOption,1)-WEEKDAY(DATE(Calendar4Year,Calendar4MonthOption,1),WeekdayOption)} -> 45600 | C59: 45601 | D59: Notes:
B62: =TEXT(DATE(Calendar4Year,Calendar4MonthOption+1,1),"mmmm") -> November | H62: =YEAR(DATE(Calendar4Year,Calendar4MonthOption+1,1)) -> 2024
B63: =UPPER(TEXT(B64,"dddd")) -> MONDAY | C63: =UPPER(TEXT(C64,"dddd")) -> TUESDAY | D63: =UPPER(TEXT(D64,"dddd")) -> WEDNESDAY | E63: =UPPER(TEXT(E64,"dddd")) -> THURSDAY | F63: =UPPER(TEXT(F64,"dddd")) -> FRIDAY | G63: =UPPER(TEXT(G64,"dddd")) -> SATURDAY | H63: =UPPER(TEXT(H64,"dddd")) -> SUNDAY
B64: {=Days+1+DATE(Calendar5Year,Calendar5MonthOption,1)-WEEKDAY(DATE(Calendar5Year,Calendar5MonthOption,1),WeekdayOption)} -> 45593 | C64: 45594 | D64: 45595 | E64: 45596 | F64: 45597 | G64: 45598 | H64: 45599
B66: {=Days+8+DATE(Calendar5Year,Calendar5MonthOption,1)-WEEKDAY(DATE(Calendar5Year,Calendar5MonthOption,1),WeekdayOption)} -> 45600 | C66: 45601 | D66: 45602 | E66: 45603 | F66: 45604 | G66: 45605 | H66: 45606
B68: {=Days+15+DATE(Calendar5Year,Calendar5MonthOption,1)-WEEKDAY(DATE(Calendar5Year,Calendar5MonthOption,1),WeekdayOption)} -> 45607 | C68: 45608 | D68: 45609 | E68: 45610 | F68: 45611 | G68: 45612 | H68: 45613
B70: {=Days+22+DATE(Calendar5Year,Calendar5MonthOption,1)-WEEKDAY(DATE(Calendar5Year,Calendar5MonthOption,1),WeekdayOption)} -> 45614 | C70: 45615 | D70: 45616 | E70: 45617 | F70: 45618 | G70: 45619 | H70: 45620
...

Sheet Schedule
B1: Vinh's Schedule | L1: Color Description
G2: SCHEDULE START | H2: TIME INTERVAL | M2: Blocked
G3: 0.33333333 | H3: 60 MIN | M3: Available
M4: WIMTACH - booked
C5: 45487 | D5: 45488 | E5: 45489 | F5: 45490 | G5: 45491 | H5: 45492 | I5: 45493 | M5: WIMTACH
B6: TIME | C6: SUNDAY | D6: MONDAY | E6: TUESDAY | F6: WEDNESDAY | G6: THURSDAY | H6: FRIDAY | I6: SATURDAY
B7: =ScheduleStart -> 0.33333333
B8: =B7+Increment -> 0.375
B9: =B8+Increment -> 0.41666667
B10: =B9+Increment -> 0.45833333
B11: =B10+Increment -> 0.5 | E11: external team meeting
B12: =B11+Increment -> 0.54166667 | E12: external team meeting
B13: =B12+Increment -> 0.58333333
B14: =B13+Increment -> 0.625 | H14: meeting with Prof Viji
B15: =B14+Increment -> 0.66666667
B16: =B15+Increment -> 0.70833333
B17: =B16+Increment -> 0.75 | H17: meeting with Prof Viji
B18: =B17+Increment -> 0.79166667

Sheet Sheet9
P1: Patient Encounter | R1: Spectrophotometer | S1: Pulse Oximeter | U1: ABG | V1: Wave Form
A2: group | B2: Row Labels | C2: Count of group | P2: Patient | Q2: Encounter | R2: Spectrophotometer | S2: Device | T2: Pulseoximeter | U2: Blood gas | V2: 2HZ | W2: PPG | X2: Base
A3: Forehead (E) | B3: Back Earlobe (F) | C3: 186 | P3: patient_id | Q3: encounter_id | R3: patient_id | S3: device_number | T3: encounter_id | U3: patient_id | V3: encounter_id* | W3: encounter_id* | X3: encounter_id*
A4: Inner Upper Arm (D) | B4: Calf | C4: 39 | P4: site_id | Q4: encounter_date | R4: encounter_id | S4: device_type | T4: device | U4: encounter_id | V4: Sample | W4: RED | X4: ECG-II
A5: Inner Upper Arm (D) | B5: Cheek (I) | C5: 186 | P5: assigned_sex | Q5: age_at_encounter | R5: group | S5: light_type | T5: probe_location | U5: type | V5: ETCO2 | W5: IR | X5: ETO2
A6: Palmar (C) | B6: Dorsal (B) | C6: 1122 | P6: race | Q6: warming | R6: date | T6: sample_number | U6: date | V6: ETO2 | X6: ETCO2
A7: Palmar (C) | B7: Fingernail (A) | C7: 1117 | P7: ethnicity | Q7: fitzpatrick | R7: melanin_index | T7: saturation | U7: time | V7: ScalcO2 | X7: RR
A8: Palmar (C) | B8: Forehead (E) | C8: 1122 | Q8: monk_fingernail | R8: hb_index | T8: pi | U8: sample | V8: RR | X8: ART
A9: Dorsal (B) | B9: Front Earlobe (E) | C9: 186 | Q9: monk_dorsal | R9: hb_so2_index | U9: ph | V9: dev60_SpO2
A10: Dorsal (B) | B10: Inner Upper Arm (D) | C10: 1125 | Q10: monk_palmar | R10: hue | U10: pco2 | V10: dev60_HR
A11: Dorsal (B) | B11: Nare (H) | C11: 186 | Q11: monk_upper_arm | R11: value | U11: po2 | V11: dev60_PI
A12: Fingernail (A) | B12: Palmar (C) | C12: 1125 | Q12: monk_forehead | R12: chroma | U12: so2 | V12: dev59_SpO2
A13: Fingernail (A) | B13: (blank) | Q13: finger_l1_device | R13: lab_l | U13: cohb | V13: dev59_HR
A14: Fingernail (A) | B14: Grand Total | C14: 6394 | Q14: finger_l2_device | R14: lab_a | U14: methb | V14: dev59_PI
A15: Inner Upper Arm (D) | Q15: finger_l3_device | R15: lab_b | U15: thb | V15: Timestamp
A16: Forehead (E) | Q16: finger_l4_device | R16: km400 | U16: k
A17: Forehead (E) | Q17: finger_l5_device | R17: km410 | U17: na
A18: Cheek (I) | Q18: finger_r1_device | R18: km420 | U18: ca
A19: Cheek (I) | Q19: finger_r2_device | R19: km430 | U19: cl
A20: Back Earlobe (F) | Q20: finger_r3_device | R20: km440 | U20: glucose
A21: Back Earlobe (F) | Q21: finger_r4_device | R21: km450 | U21: lactate
A22: Back Earlobe (F) | Q22: finger_r5_device | R22: km460 | U22: p50
A23: Forehead (E) | Q23: finger_l1_diameter | R23: km470 | U23: cbase
A24: Forehead (E) | Q24: finger_l2_diameter | R24: km480 | U24: ETCO2
A25: Forehead (E) | Q25: finger_l3_diameter | R25: km490 | U25: ETO2
A26: Fingernail (A) | Q26: finger_l4_diameter | R26: km500 | U26: ScalcO2
A27: Nare (H) | Q27: finger_l5_diameter | R27: km510 | U27: RR
... A31: Front Earlobe (E) | Q31: finger_r4_diameter | R31: km550 | U31: dev64_HR
A32: Front Earlobe (E) | Q32: finger_r5_diameter | R32: km560
A33: Front Earlobe (E) | R33: km570
A34: Inner Upper Arm (D) | R34: km580
A35: Fingernail (A) | R35: km590
A36: Dorsal (B) | R36: km600
A37: Dorsal (B) | R37: km610
A38: Dorsal (B) | R38: km620
A39: Palmar (C) | R39: km630
A40: Palmar (C) | R40: km640
A41: Palmar (C) | R41: km650
A42: Inner Upper Arm (D) | R42: km660
A43: Inner Upper Arm (D) | R43: km670
...

Sheet wf folder
A1: Folder | B1: Encounter_id | C1: .dat (150hz) | D1: .hea (150hz) | E1: _ppg.dat (PPG) | F1: _ppg.hea (PPG) | G1: .csv (2hz) | H1: Total files | I1: 150hz | J1: PPG | K1: 2hz
A2: 0 | B2: 0b16e4aacb8222e62a981fc0d5ef2cac96d2360806f2132fd5596c244b01bec0 | C2: No | D2: Yes | E2: No | F2: No | G2: Yes | H2: =COUNTIF(Table1[[#This Row],[.dat (150hz)]:[.csv (2hz)]],"Yes") -> 2 | I2: =IF(AND(Table1[[#This Row],[.dat (150hz)]]="Yes",Table1[[#This Row],[.hea (150hz)]]="Yes"),"Yes","No") -> No | J2: =IF(AND(Table1[[#This Row],[_ppg.dat (PPG)]]="Yes",Table1[[#This Row],[_ppg.hea (PPG)]]="Yes"),"Yes","No") -> No | K2: =Table1[[#This Row],[.csv (2hz)]] -> Yes
A3: 0 | B3: 0b60fef56286b168b44d5d0c935a40c042b8ad60b5160f9655f9068d0265dcb4 | C3: No | D3: No | E3: No | F3: No | G3: Yes | H3: =COUNTIF(Table1[[#This Row],[.dat (150hz)]:[.csv (2hz)]],"Yes") -> 1 | I3: =IF(AND(Table1[[#This Row],[.dat (150hz)]]="Yes",Table1[[#This Row],[.hea (150hz)]]="Yes"),"Yes","No") -> No | J3: =IF(AND(Table1[[#This Row],[_ppg.dat (PPG)]]="Yes",Table1[[#This Row],[_ppg.hea (PPG)]]="Yes"),"Yes","No") -> No | K3: =Table1[[#This Row],[.csv (2hz)]] -> Yes
A4: 0 | B4: 0c4add4ddcafc4e85656b66e0ac81943fb5463d6540702358e65e8d840d87f68 | C4: Yes | D4: No | E4: Yes | F4: Yes | G4: No | H4: =COUNTIF(Table1[[#This Row],[.dat (150hz)]:[.csv (2hz)]],"Yes") -> 3 | I4: =IF(AND(Table1[[#This Row],[.dat (150hz)]]="Yes",Table1[[#This Row],[.hea (150hz)]]="Yes"),"Yes","No") -> No | J4: =IF(AND(Table1[[#This Row],[_ppg.dat (PPG)]]="Yes",Table1[[#This Row],[_ppg.hea (PPG)]]="Yes"),"Yes","No") -> Yes | K4: =Table1[[#This Row],[.csv (2hz)]] -> No
A5: 0 | B5: 0d2f8ecfd8300330cb7e232b27be416b9dd3fc84a6060dc4a68811b28f568ed9 | C5: Yes | D5: Yes | E5: Yes | F5: No | G5: No | H5: =COUNTIF(Table1[[#This Row],[.dat (150hz)]:[.csv (2hz)]],"Yes") -> 3 | I5: =IF(AND(Table1[[#This Row],[.dat (150hz)]]="Yes",Table1[[#This Row],[.hea (150hz)]]="Yes"),"Yes","No") -> Yes | J5: =IF(AND(Table1[[#This Row],[_ppg.dat (PPG)]]="Yes",Table1[[#This Row],[_ppg.hea (PPG)]]="Yes"),"Yes","No") -> No | K5: =Table1[[#This Row],[.csv (2hz)]] -> No
A6: 0 | B6: 0ec044d3994e9c9f063f9fc436c34a83ec5bc764993b7287f6ccd58f7ebb7375 | C6: No | D6: No | E6: No | F6: Yes | G6: Yes | H6: =COUNTIF(Table1[[#This Row],[.dat (150hz)]:[.csv (2hz)]],"Yes") -> 2 | I6: =IF(AND(Table1[[#This Row],[.dat (150hz)]]="Yes",Table1[[#This Row],[.hea (150hz)]]="Yes"),"Yes","No") -> No | J6: =IF(AND(Table1[[#This Row],[_ppg.dat (PPG)]]="Yes",Table1[[#This Row],[_ppg.hea (PPG)]]="Yes"),"Yes","No") -> No | K6: =Table1[[#This Row],[.csv (2hz)]] -> Yes
A7: 0 | B7: 0fe6279f59badfef7e6fe31ba2786b9102d9323dca4aeef426c1d8a81451b54e | C7: Yes | D7: Yes | E7: No | F7: No | G7: No | H7: =COUNTIF(Table1[[#This Row],[.dat (150hz)]:[.csv (2hz)]],"Yes") -> 2 | I7: =IF(AND(Table1[[#This Row],[.dat (150hz)]]="Yes",Table1[[#This Row],[.hea (150hz)]]="Yes"),"Yes","No") -> Yes | J7: =IF(AND(Table1[[#This Row],[_ppg.dat (PPG)]]="Yes",Table1[[#This Row],[_ppg.hea (PPG)]]="Yes"),"Yes","No") -> No | K7: =Table1[[#This Row],[.csv (2hz)]] -> No
A8: 0 | B8: 01b0a887f76a3f77a708ccff97cabb16b223e572c4bfd18c4ff02c443c0c88d3 | C8: No | D8: Yes | E8: No | F8: No | G8: No | H8: =COUNTIF(Table1[[#This Row],[.dat (150hz)]:[.csv (2hz)]],"Yes") -> 1 | I8: =IF(AND(Table1[[#This Row],[.dat (150hz)]]="Yes",Table1[[#This Row],[.hea (150hz)]]="Yes"),"Yes","No") -> No | J8: =IF(AND(Table1[[#This Row],[_ppg.dat (PPG)]]="Yes",Table1[[#This Row],[_ppg.hea (PPG)]]="Yes"),"Yes","No") -> No | K8: =Table1[[#This Row],[.csv (2hz)]] -> No
A9: 0 | B9: 08ba900fdba98789f68c8559387b0d96995484a65b782381f804004557427323 | C9: No | D9: Yes | E9: No | F9: No | G9: Yes | H9: =COUNTIF(Table1[[#This Row],[.dat (150hz)]:[.csv (2hz)]],"Yes") -> 2 | I9: =IF(AND(Table1[[#This Row],[.dat (150hz)]]="Yes",Table1[[#This Row],[.hea (150hz)]]="Yes"),"Yes","No") -> No | J9: =IF(AND(Table1[[#This Row],[_ppg.dat (PPG)]]="Yes",Table1[[#This Row],[_ppg.hea (PPG)]]="Yes"),"Yes","No") -> No | K9: =Table1[[#This Row],[.csv (2hz)]] -> Yes
A10: 0 | B10: 08c9ab93ed93d62d796dcfd6bb03197cd26f74f7585512d7fea7c2599edc090f | C10: No | D10: Yes | E10: No | F10: No | G10: No | H10: =COUNTIF(Table1[[#This Row],[.dat (150hz)]:[.csv (2hz)]],"Yes") -> 1 | I10: =IF(AND(Table1[[#This Row],[.dat (150hz)]]="Yes",Table1[[#This Row],[.hea (150hz)]]="Yes"),"Yes","No") -> No | J10: =IF(AND(Table1[[#This Row],[_ppg.dat (PPG)]]="Yes",Table1[[#This Row],[_ppg.hea (PPG)]]="Yes"),"Yes","No") -> No | K10: =Table1[[#This Row],[.csv (2hz)]] -> No
A11: 0 | B11: 039d6278a1f20423ec2955be8ae305283887dc67fc5f3a04aa17ac01172c5b2f | C11: No | D11: Yes | E11: No | F11: No | G11: Yes | H11: =COUNTIF(Table1[[#This Row],[.dat (150hz)]:[.csv (2hz)]],"Yes") -> 2 | I11: =IF(AND(Table1[[#This Row],[.dat (150hz)]]="Yes",Table1[[#This Row],[.hea (150hz)]]="Yes"),"Yes","No") -> No | J11: =IF(AND(Table1[[#This Row],[_ppg.dat (PPG)]]="Yes",Table1[[#This Row],[_ppg.hea (PPG)]]="Yes"),"Yes","No") -> No | K11: =Table1[[#This Row],[.csv (2hz)]] -> Yes
A12: 0 | B12: 072c1f59d1ac101545d5919c8aec72686c4753de3c8c3a7f44ca774aff945fd4 | C12: No | D12: Yes | E12: No | F12: No | G12: Yes | H12: =COUNTIF(Table1[[#This Row],[.dat (150hz)]:[.csv (2hz)]],"Yes") -> 2 | I12: =IF(AND(Table1[[#This Row],[.dat (150hz)]]="Yes",Table1[[#This Row],[.hea (150hz)]]="Yes"),"Yes","No") -> No | J12: =IF(AND(Table1[[#This Row],[_ppg.dat (PPG)]]="Yes",Table1[[#This Row],[_ppg.hea (PPG)]]="Yes"),"Yes","No") -> No | K12: =Table1[[#This Row],[.csv (2hz)]] -> Yes
A13: 0 | B13: 081dc6212afe2082cc0f84c06ce0bcad2296a897de6800739a66171e598fe300 | C13: Yes | D13: No | E13: No | F13: No | G13: No | H13: =COUNTIF(Table1[[#This Row],[.dat (150hz)]:[.csv (2hz)]],"Yes") -> 1 | I13: =IF(AND(Table1[[#This Row],[.dat (150hz)]]="Yes",Table1[[#This Row],[.hea (150hz)]]="Yes"),"Yes","No") -> No | J13: =IF(AND(Table1[[#This Row],[_ppg.dat (PPG)]]="Yes",Table1[[#This Row],[_ppg.hea (PPG)]]="Yes"),"Yes","No") -> No | K13: =Table1[[#This Row],[.csv (2hz)]] -> No
... A105: 8 | B105: 8c3a751621bd15f7747f246ff5893c83ea8e7c6e7629bae22a4631be8d4729b4 | C105: No | D105: No | E105: Yes | F105: No | G105: No | H105: =COUNTIF(Table1[[#This Row],[.dat (150hz)]:[.csv (2hz)]],"Yes") -> 1 | I105: =IF(AND(Table1[[#This Row],[.dat (150hz)]]="Yes",Table1[[#This Row],[.hea (150hz)]]="Yes"),"Yes","No") -> No | J105: =IF(AND(Table1[[#This Row],[_ppg.dat (PPG)]]="Yes",Table1[[#This Row],[_ppg.hea (PPG)]]="Yes"),"Yes","No") -> No | K105: =Table1[[#This Row],[.csv (2hz)]] -> No
A106: a | B106: afab7dd573698488d371aa2c81c0a5f8b2805593484edbea54964e5286cfec9d | C106: No | D106: No | E106: Yes | F106: Yes | G106: No | H106: =COUNTIF(Table1[[#This Row],[.dat (150hz)]:[.csv (2hz)]],"Yes") -> 2 | I106: =IF(AND(Table1[[#This Row],[.dat (150hz)]]="Yes",Table1[[#This Row],[.hea (150hz)]]="Yes"),"Yes","No") -> No | J106: =IF(AND(Table1[[#This Row],[_ppg.dat (PPG)]]="Yes",Table1[[#This Row],[_ppg.hea (PPG)]]="Yes"),"Yes","No") -> Yes | K106: =Table1[[#This Row],[.csv (2hz)]] -> No
A107: a | B107: a884dac2728322432d627ca873a4afd427866e09e5487c613f15d28dfdc44410 | C107: No | D107: No | E107: No | F107: No | G107: Yes | H107: =COUNTIF(Table1[[#This Row],[.dat (150hz)]:[.csv (2hz)]],"Yes") -> 1 | I107: =IF(AND(Table1[[#This Row],[.dat (150hz)]]="Yes",Table1[[#This Row],[.hea (150hz)]]="Yes"),"Yes","No") -> No | J107: =IF(AND(Table1[[#This Row],[_ppg.dat (PPG)]]="Yes",Table1[[#This Row],[_ppg.hea (PPG)]]="Yes"),"Yes","No") -> No | K107: =Table1[[#This Row],[.csv (2hz)]] -> Yes
A108: a | B108: a462d52bc71cd1c975cbe9e192be856dfe0b0b0e7e630d95944fcec8abf5a046 | C108: No | D108: No | E108: No | F108: Yes | G108: No | H108: =COUNTIF(Table1[[#This Row],[.dat (150hz)]:[.csv (2hz)]],"Yes") -> 1 | I108: =IF(AND(Table1[[#This Row],[.dat (150hz)]]="Yes",Table1[[#This Row],[.hea (150hz)]]="Yes"),"Yes","No") -> No | J108: =IF(AND(Table1[[#This Row],[_ppg.dat (PPG)]]="Yes",Table1[[#This Row],[_ppg.hea (PPG)]]="Yes"),"Yes","No") -> No | K108: =Table1[[#This Row],[.csv (2hz)]] -> No
A109: a | B109: a63d9e9c845110811a4405e9c46a3523d1e379bfde1c6d48a329b1083f1d1d33 | C109: No | D109: No | E109: No | F109: No | G109: Yes | H109: =COUNTIF(Table1[[#This Row],[.dat (150hz)]:[.csv (2hz)]],"Yes") -> 1 | I109: =IF(AND(Table1[[#This Row],[.dat (150hz)]]="Yes",Table1[[#This Row],[.hea (150hz)]]="Yes"),"Yes","No") -> No | J109: =IF(AND(Table1[[#This Row],[_ppg.dat (PPG)]]="Yes",Table1[[#This Row],[_ppg.hea (PPG)]]="Yes"),"Yes","No") -> No | K109: =Table1[[#This Row],[.csv (2hz)]] -> Yes
A110: a | B110: a9e0c7c0dc74357db0410e7b8f50ba06396aa9fa17f6e7d243366cd8ce72c5e3 | C110: No | D110: Yes | E110: No | F110: No | G110: No | H110: =COUNTIF(Table1[[#This Row],[.dat (150hz)]:[.csv (2hz)]],"Yes") -> 1 | I110: =IF(AND(Table1[[#This Row],[.dat (150hz)]]="Yes",Table1[[#This Row],[.hea (150hz)]]="Yes"),"Yes","No") -> No | J110: =IF(AND(Table1[[#This Row],[_ppg.dat (PPG)]]="Yes",Table1[[#This Row],[_ppg.hea (PPG)]]="Yes"),"Yes","No") -> No | K110: =Table1[[#This Row],[.csv (2hz)]] -> No
A111: a | B111: a9b5f9424b3c0b6f0cdef6d2a69e926ac6cf6101d70c9bb46d4aafa7b3ae131a | C111: No | D111: Yes | E111: No | F111: No | G111: No | H111: =COUNTIF(Table1[[#This Row],[.dat (150hz)]:[.csv (2hz)]],"Yes") -> 1 | I111: =IF(AND(Table1[[#This Row],[.dat (150hz)]]="Yes",Table1[[#This Row],[.hea (150hz)]]="Yes"),"Yes","No") -> No | J111: =IF(AND(Table1[[#This Row],[_ppg.dat (PPG)]]="Yes",Table1[[#This Row],[_ppg.hea (PPG)]]="Yes"),"Yes","No") -> No | K111: =Table1[[#This Row],[.csv (2hz)]] -> No
A112: a | B112: a7fd8314144b307e12b50bfd8db9a6e7cbafc3ffd6314fbed544f1976e60463d | C112: Yes | D112: No | E112: No | F112: No | G112: No | H112: =COUNTIF(Table1[[#This Row],[.dat (150hz)]:[.csv (2hz)]],"Yes") -> 1 | I112: =IF(AND(Table1[[#This Row],[.dat (150hz)]]="Yes",Table1[[#This Row],[.hea (150hz)]]="Yes"),"Yes","No") -> No | J112: =IF(AND(Table1[[#This Row],[_ppg.dat (PPG)]]="Yes",Table1[[#This Row],[_ppg.hea (PPG)]]="Yes"),"Yes","No") -> No | K112: =Table1[[#This Row],[.csv (2hz)]] -> No
A113: a | B113: a5f20e2d8cf75b1e928bf6faa67b5bc1c1bb1b528c9ba77fb574d6f741e805b0 | C113: No | D113: Yes | E113: No | F113: No | G113: No | H113: =COUNTIF(Table1[[#This Row],[.dat (150hz)]:[.csv (2hz)]],"Yes") -> 1 | I113: =IF(AND(Table1[[#This Row],[.dat (150hz)]]="Yes",Table1[[#This Row],[.hea (150hz)]]="Yes"),"Yes","No") -> No | J113: =IF(AND(Table1[[#This Row],[_ppg.dat (PPG)]]="Yes",Table1[[#This Row],[_ppg.hea (PPG)]]="Yes"),"Yes","No") -> No | K113: =Table1[[#This Row],[.csv (2hz)]] -> No
A114: a | B114: a4bc42d28b12c8e42c01953344128a42ef1ef3fe722214264b9eb7d8e5749456 | C114: No | D114: Yes | E114: No | F114: No | G114: No | H114: =COUNTIF(Table1[[#This Row],[.dat (150hz)]:[.csv (2hz)]],"Yes") -> 1 | I114: =IF(AND(Table1[[#This Row],[.dat (150hz)]]="Yes",Table1[[#This Row],[.hea (150hz)]]="Yes"),"Yes","No") -> No | J114: =IF(AND(Table1[[#This Row],[_ppg.dat (PPG)]]="Yes",Table1[[#This Row],[_ppg.hea (PPG)]]="Yes"),"Yes","No") -> No | K114: =Table1[[#This Row],[.csv (2hz)]] -> No
